mock matchers › failing output › expect.mock.nthReturnedWith threw exception
<dim>expect.mock(</dim><red>mock</red><dim>).nthReturnedWith(</dim><green>expected</green><dim>)</dim> <dim>/* using == */</dim>

Expected the first call to the mock function to have returned:
  <green>2</green>
But the call raised:
  <red>Division_by_zero</red>
