FnMatchers â€º FnMatchers failure output
Running 1 test suite
<red><bold><inverse> FAIL </inverse></bold></red> <whiteBright>FnMatchers failure output</whiteBright>
<bold><red>  \226\128\162 FnMatchers failure output \226\128\186 Expect to throw, but doesn't</red></bold>

    <dim>expect.fn(</dim><red>function</red><dim>).toThrow(</dim><green></green><dim>)</dim>
    
    Expected the function to throw an error.
    But it didn't throw anything.

<bold><red>  \226\128\162 FnMatchers failure output \226\128\186 Expect not to throw and does</red></bold>

    <dim>expect.fn(</dim><red>function</red><dim>)toThrow(</dim><green></green><dim>)</dim>
    
    Expected the function not to throw an error.
    Instead, it threw: 
      <red>(Invalid_argument \"the earth is flat\")</red>

<bold><red>  \226\128\162 FnMatchers failure output \226\128\186 Expect the wrong exception</red></bold>

    <dim>expect.fn(</dim><red>function</red><dim>).toThrowException(</dim><green>exception</green><dim>)</dim>
    
    Expected the function to throw an error matching:
      <green>(Invalid_argument \"with some other message\")</green>
    Instead, it threw:
      <red>(Invalid_argument \"with some message\")</red>

<bold><red>  \226\128\162 FnMatchers failure output \226\128\186 Expect an exception that doesn't throw</red></bold>

    <dim>expect.fn(</dim><red>function</red><dim>).toThrowException(</dim><green>exception</green><dim>)</dim>
    
    Expected the function to throw an error matching:
      <green>Not_found</green>
    But it didn't throw anything.


<whiteBright><bold>Test Suites: </bold></whiteBright><red><bold>1 failed</bold></red>, 0 passed, 1 total
<whiteBright><bold>Tests:       </bold></whiteBright><red><bold>4 failed</bold></red>, 0 passed, 4 total
<whiteBright><bold>Time:        </bold></whiteBright>< 1ms

