mock matchers › failing output › expect.mock.toThrowException no exception
<dim>expect.mock(</dim><red>function</red><dim>).toThrowException(</dim><green>exception</green><dim>)</dim>

Expected the function to throw an error matching:
  <green>Not_found</green>
But it didn't throw anything.
