mock matchers › failing output › expect.mock.toThrowException multiple wrong exceptions
<dim>expect.mock(</dim><red>function</red><dim>).toThrowException(</dim><green>exception</green><dim>)</dim>

Expected the function to throw an error matching:
  <green>Not_found</green>
Instead, it threw:
  <red>Division_by_zero</red>, <red>Division_by_zero</red>
